Workbook

Sheet Checklist
B2: Checklist - BI com IA
B6: Funcionalidade | C6: ID | D6: Cenário | E6: Regras de Validação | F6: Resultado Esperado | G6: Fluxo | H6: Categoria | I6: Status QA Ciclo I | J6: Status QA Ciclo II | K6: Observações
B7: Tela 01 - Login | C7: 1 | D7: Login com sucesso | E7: Usuário e senha válidos e cadastrados | F7: Usuário e senha válidos e cadastrados | G7: FP | H7: Funcionalidade | I7: Passed
B8: Tela 01 - Login | C8: 2 | D8: Login sem sucesso | E8: Campo vazio | F8: O campo deve estar preenchido | G8: FE | H8: Funcionalidade | I8: Passed | K8: Preencha este Campo
B9: Tela 01 - Login | C9: 3 | E9: Usuário não cadastrado no sistema | F9: Exibir mensagem de erro informando usuário inválido | G9: FE | H9: Funcionalidade | I9: Passed | K9: Invalid username or password
B10: Tela 01 - Login | C10: 4 | D10: Campo Usuário | E10: Inserir usuário com caracteres acima do máximo permitido | F10: Sistema limita a digitação ou exibe mensagem de erro | G10: FE | H10: Funcionalidade | I10: Passed | K10: Invalid username or password
B11: Tela 01 - Login | C11: 5 | E11: Injeção de SQL no campo Usuário (Inserir ' OR '1'='1 no campo Usuário) | F11: Sistema rejeita entrada e não permite acesso indevido | G11: FE | H11: Segurança | I11: Passed | K11: Invalid username or password
B12: Tela 01 - Login | C12: 6 | E12: Inserir usuário com capitalização diferente do cadastrado | F12: Sistema autentica (case insensitive) ou rejeita conforme regra | G12: FA | H12: Funcionalidade | I12: Passed | K12: Invalid username or password
B13: Tela 01 - Login | C13: 7 | D13: Login com campos em branco | E13: Campos usuário + senha | F13: Mensagem de campo obrigatório nos dois campos | G13: FE | H13: Funcionalidade | I13: Passed | K13: Preencha este Campo no campo usuário
B14: Tela 01 - Login | C14: 8 | E14: Campo usuário | F14: Mensagem de campo obrigatório no campo Usuário | G14: FE | H14: Funcionalidade | I14: Passed | K14: Preencha este Campo no campo senha
B15: Tela 01 - Login | C15: 9 | E15: Campo senha | F15: Mensagem de campo obrigatório no campo Senha | G15: FE | H15: Funcionalidade | I15: Passed | K15: Preencha este Campo no campo usuário
B16: Tela 01 - Login | C16: 10 | D16: Login com senha válida | E16: Senha válida | F16: Login realizado com sucesso | H16: Funcionalidade | I16: NA
B17: Tela 01 - Login | C17: 11 | D17: Login com senha inválida | E17: Campo vazio | F17: O campo deve estar preenchido | G17: FE | H17: Funcionalidade | I17: Passed | K17: Preencha este Campo no campo senha
B18: Tela 01 - Login | C18: 12 | E18: Senha incorreta | F18: Usuário ou senha inválidos | G18: FE | H18: Funcionalidade | I18: Passed | K18: Invalid username or password
B19: Tela 01 - Login | C19: 13 | E19: Com espaços | F19: A senha não pode conter espaços | G19: FE | H19: Funcionalidade | I19: Passed | K19: Invalid username or password
B20: Tela 01 - Login | C20: 14 | D20: Checbox - Lembrar de mim | E20: Marcar checkbox, logar, fechar e reabrir o navegador | F20: Usuário mantido logado ou campos preenchidos automaticamente | G20: FA | H20: Sessão/Auth | I20: Failed | K20: Usuário não se manteve logado e campos não continuaram preenchidos
B21: Tela 01 - Login | C21: 15 | E21: Login sem marcar checkbox, fechar e reabrir o navegador | F21: Sessão encerrada e campos em branco ao reabrir | G21: FA | H21: Sessão/Auth | I21: Passed
B22: Tela 01 - Login | C22: 16 | E22: Marcar checkbox, logar, aguardar expiração de sessão | F22: Sistema renova sessão automaticamente sem novo login | G22: FA | H22: Sessão/Auth | I22: Failed | K22: Sessão não expira
B23: Tela 01 - Login | C23: 17 | E23: Marcar checkbox no Chrome, acessar o mesmo link no Firefox | F23: Sessão lembrada não compartilhada entre navegadores | G23: FA | H23: Compatibilidade | I23: Failed | K23: Sistema não mantem logado ou dados preenchidos em nenhum navegador
B24: Tela 01 - Login | C24: 18 | E24: Marcar checkbox, logar, limpar cookies e reabrir o sistema | F24: Sistema solicita novo login (cookie removido) | G24: FE | H24: Segurança | I24: Failed | K24: Usuário não se manteve logado e campos não continuaram preenchidos
B25: Tela 01 - Login | C25: 19 | D25: Campo Usuário + Senha | E25: Realizar múltiplas tentativas de login com credenciais erradas | F25: Sistema bloqueia acesso ou exibe CAPTCHA após X tentativas | G25: FE | H25: Segurança | I25: Failed | K25: Sistema não tem limite de tentativas
B26: Tela 01 - Login | C26: 20 | E26: Clicar duas vezes rapidamente no botão 'Entrar' | F26: Sistema processa apenas uma requisição, sem duplicidade | G26: FE | H26: Performance | I26: Passed
B27: Tela 01 - Login | C27: 21 | E27: Após autenticar com sucesso, pressionar F5 | F27: Sessão mantida; usuário não redirecionado para login novamente | G27: FA | H27: Sessão/Auth | I27: Passed
B28: Tela 01 - Login | C28: 22 | E28: Navegar pelos campos e botão usando Tab e Enter | F28: Todos os elementos acessíveis e funcionais via teclado | G28: FA | H28: Acessibilidade | I28: Passed
B29: Tela 01 - Login | C29: 23 | D29: Responsividade/Acessibilidade | E29: Acessar a tela de login em resolução Descktop(800x600) | F29: Layout se adapta corretamente; todos os elementos visíveis e funcionais | G29: FA | H29: Compatibilidade | I29: Passed
B30: Tela 01 - Login | C30: 24 | E30: Acessar a tela de login em resolução mobile | F30: Layout exibido conforme design original com duas colunas | G30: FP | H30: Compatibilidade | I30: Passed
B31: Tela 01 - Login | C31: 25 | E31: Acessar a tela de login em diferentes navegadores (Chrome, Edge) | F31: Tela renderiza corretamente em todos os navegadores | G31: FA | H31: Compatibilidade | I31: Passed
B32: Tela 01 - Login | C32: 26 | E32: Navegar pelos campos e botão usando Tab e Enter | F32: Todos os elementos acessíveis e funcionais via teclado; ordem de tabulação lógica | G32: FA | H32: Acessibilidade | I32: Passed
B33: Tela 01 - Login | C33: 27 | D33: Campo Senha | E33: Inserir senha com somente 1 caractere | F33: Mensagem de erro: senha deve ter no minimo 6 caracteres | G33: FE | H33: Funcionalidade | I33: Passed
B34: Tela 01 - Login | C34: 28 | E34: Inserir senha com caracteres acima do máximo permitido | F34: Sistema limita a digitação ou exibe mensagem de erro | G34: FE | H34: Funcionalidade | I34: Failed | K34: Senha não tem limitação de caracteres
B35: Tela 01 - Login | C35: 29 | E35: Clicar no ícone de olho no campo Senha | F35: Conteúdo da senha exibido em texto legível | G35: FA | H35: Usabilidade | I35: Passed
B36: Tela 01 - Login | C36: 30 | E36: Clicar novamente no ícone de olho após senha visível | F36: Conteúdo da senha ocultado (asteriscos/pontos) | G36: FA | H36: Usabilidade | I36: Passed
B37: Tela 01 - Login | C37: 31 | E37: Colar texto no campo senha | F37: Sistema aceita senha colada e autentica normalmente | G37: FA | H37: Funcionalidade | I37: Passed
B38: Tela 01 - Login | C38: 32 | E38: Inspecionar campo senha via dev tools do navegador | F38: Tipo do campo é 'password'; valor não exposto em texto puro no DOM | G38: FE | H38: Segurança | I38: Passed
B39: Tela 01 - Login | C39: 33 | E39: Inserir senha correta com capitalização diferente (ex: 'Senha123' → 'senha123') | F39: Sistema rejeita e informa credenciais inválidas | G39: FE | H39: Segurança | I39: Passed
B40: Tela 01 - Login | C40: 34 | D40: Redirecionamento/Concorrência | E40: Acessar a tela de login já estando autenticado | F40: Sistema redireciona para a página principal (dashboard) | G40: FA | H40: Sessão/Auth | I40: Passed
B41: Tela 01 - Login | C41: 35 | E41: Clicar no botão 'Voltar' do navegador após login com sucesso | F41: Usuário não retorna à tela de login; sessão permanece ativa | G41: FA | H41: Sessão/Auth | I41: Passed
B42: Tela 01 - Login | C42: 36 | E42: Realizar logout e clicar no botão 'Voltar' do navegador | F42: Usuário não acessa área autenticada; permanece na tela de login | G42: FE | H42: Segurança | I42: Failed | K42: O sistema permite que o usuário volte logado mesmo saindo da pagina e retornando
B43: Tela 01 - Login | C43: 37 | E43: Acessar URL protegida sem login, autenticar e verificar redirecionamento | F43: Após login, sistema redireciona para a URL originalmente solicitada | G43: FA | H43: Funcionalidade | I43: Passed
B44: Tela 01 - Login | C44: 38 | E44: Realizar login com o mesmo usuário em dois navegadores simultaneamente | F44: Sistema permite ou invalida sessão anterior conforme regra de negócio | G44: FA | H44: Sessão/Auth | I44: Failed | K44: Sistema permite acesso com dois usuários em navegadores diferentes
...

Sheet Bugs I
A1: ID | B1: Título | C1: Criticidade | D1: Status Dev | E1: Status QA | F1: ESTÁ NO JIRA
A2: 123 | B2: Campo de "Pesquisar" na barra lateral bloqueia digitação e abre modal indevidamente | C2: Médio | F2: SIM
A3: 14 | B3: Mesmo marcando o checkbox "Lembrar de mim" o usuário não se manteve logado e campos não continuaram preenchidos | C3: Médio | F3: SIM
A4: 16 | B4: Sessão não expira | C4: Alto | F4: SIM
A5: 17 | B5: Sistema não mantem logado ou dados preenchidos em nenhum navegador | C5: Alto | F5: SIM
A6: 18 | B6: Usuário não se manteve logado e campos não continuaram preenchidos | C6: Alto | F6: SIM
A7: 19 | B7: O sistema permite que inumeras tentativas possam ser feitas para acessar a conta | C7: Crítico | F7: SIM
A8: 28 | B8: O sistema permite quantidade indefinida de caracteres no campo senha | C8: Médio | F8: SIM
A9: 36 | B9: O sistema permite que o usuário volte logado mesmo saindo da pagina e retornando | C9: Alto | F9: SIM
A10: 38 | B10: Sistema permite acesso com dois usuários em navegadores diferentes | C10: Alto | F10: SIM
A11: 39 | B11: Sistema permite acesso com dois usuários em dispositivos diferentes | C11: Alto | F11: SIM
A12: 41 | B12: Sessão não encerra sessão após 2hs horas | C12: Alto | F12: SIM
A13: 43 | B13: Sessão não encerra após 2:30hs | C13: Alto | F13: SIM
A14: 321-323 | B14: CT321-CT323: Modal de Configurações corta conteúdo das abas Geral e Aparência por falta de altura ou scroll interno | C14: Baixo | F14: SIM
A15: 320 | B15: Card de Gráfico Ultrapassa os Limites do Modal "Adicionar Gráfico ao Dashboard | C15: Baixo | F15: SIM
A16: 233 | B16: Formulário de Nova Licença não indica visualmente o campo obrigatório "State/Province/Region" ao falhar no salvamento | C16: Médio | F16: SIM
A17: 233 | B17: Campos 'State/Province/Region' e 'Postal Code' não são traduzidos para português ao selecionar países diferentes do Brasil | C17: Baixo | F17: SIM
A18: 238 | B18: Formulário de Nova Licença não permite salvar ao selecionar banco de dados tipo BigQuery, exibindo erro genérico não identificado | C18: Médio | F18: SIM
A19: 238 | B19: Mensagem de erro no formulário de Nova Licença exibida em inglês | C19: Baixo | F19: SIM
A20: 324 | B20: Campos Obrigatórios Não São Validados ao Criar Novo Usuário | C20: Médio | F20: SIM
A21: 325 | B21: Tooltips Ausentes ou Incorretos nos Ícones da Tela de Usuários | C21: Médio | F21: SIM
A22: 275 | B22: Sistema redireciona silenciosamente para o Chat ao tentar acessar páginas sem permissão — sem mensagem de feedback ao usuário | C22: Médio | F22: SIM
A23: 280 | B23: LLM retorna "Erro de conexão" ao processar consultas quando o usuário possui somente 2 tabelas disponíveis nas permissões | C23: Médio | F23: SIM
A24: 280 | B24: Sistema preserva dados e sessão de usuário com restrições após trocas sucessivas de usuário | C24: Crítico | F24: SIM
A25: 286 | B25: Auditoria do Sistema retorna "Erro ao carregar logs de auditoria" ao aplicar filtros — Perfil Coordenador/ADM | C25: Médio | F25: SIM
A26: 287 | B26: Tela de Permissões em Auditoria não carrega grupos disponíveis para o perfil Supervisor | C26: Médio | F26: SIM
A27: 289 | B27: Chat retorna "Erro de conexão" ao enviar mensagens com perfil Analista, impossibilitando uso do SQL | C27: Médio | F27: SIM
A28: - | B28: Tela de "Gerenciar Regras" não redimensiona ao adicionar múltiplas regras em monitores de 18 polegadas | C28: Baixo | F28: SIM
A29: 81 | B29: Modal de Sugestões de Perguntas com Layout Quebrado em Telas ≤ 18 Polegadas (Zoom 100%) | C29: Baixo | F29: SIM
A30: - | B30: Exibição de Licença de Distribuidor ao Realizar Login com Usuário ADM | C30: Alto | F30: SIM
A31: 64 | B31: Onboarding é sempre reexibido em todo login dos usuários | C31: Baixo | F31: SIM
A32: 211 | B32: Filtro por Usuário Não Funciona na Aba Conversas de Auditoria | C32: Médio | F32: SIM
A33: 223 | B33: Sessão do Usuário Inativado Permanece Aberta com Erros de Conexão em Vez de Encerramento Adequado | C33: Médio | F33: SIM
A34: - | B34: Mensagem de Erro Não Amigável ao Usuário na Falha de Importação de Dados | C34: Baixo | F34: SIM
A35: 349 | B35: Sistema não rejeita com mensagem de erro apropriada em cada caso (1) somente caracteres especiais, (2) acima do máximo de caracteres, (3) somente espaços em branco | C35: Médio | F35: SIM
A36: 352 | B36: Sistema não rejeita email duplicado | C36: Alto | F36: SIM
A37: 353 | B37: O sistema rejeita apenas a falta do "https://www" todo restante é aceito e avança para a criação da licença | C37: Médio | F37: SIM
A38: 354 | B38: O sistema aceita CEP inválido (menos dígitos) | C38: Médio | F38: SIM
A39: 355 | B39: O sistema aceita menos dígitos no preenchimento do numero | C39: Médio | F39: SIM
A40: 357 | B40: O sistema aceita caracteres especiais, espaços no nome, nome duplicado já existente | C40: Alto | F40: SIM
...

Sheet Indicadores I
A1: Executado | B1: =B2+B3 -> 502
A2: Passed | B2: =COUNTIF(Checklist!I$7:I$570,'Indicadores I'!A2) -> 421
A3: Failed | B3: =COUNTIF(Checklist!I$7:I$570,'Indicadores I'!A3) -> 81 | D3: Sprint | E3: Casos de testes | F3: Executados | G3: Indice de execução | H3: Passed | I3: Passed | J3: Failed | K3: Failed | L3: Não executado | M3: Indice de Incerteza
A4: NT | B4: =COUNTIF(Checklist!I$7:I$570,'Indicadores I'!A4) -> 0 | D4: BI com IA | E4: =B5 -> 502 | F4: =B1 -> 502 | G4: =F4/E4 -> 1 | H4: =B2 -> 421 | I4: =H4/F4 -> 0.83864542 | J4: =B3 -> 81 | K4: =J4/F4 -> 0.16135458 | L4: =B4 -> 0 | M4: =L4/E4 -> 0
A5: Total | B5: =SUM(B2:B4) -> 502
D19: Severidade
D20: Projeto | E20: Critico | F20: Critico | G20: Alto | H20: Alto | I20: Médio | J20: Médio | K20: Baixo | L20: Baixo
A21: Crítico | B21: =COUNTIF('Bugs I'!C2:C82,'Indicadores I'!A21) -> 4 | D21: BI com IA | E21: =B21 -> 4 | F21: =E21/B25 -> 0.047619048 | G21: =B22 -> 51 | H21: =G21/B25 -> 0.60714286 | I21: =B23 -> 20 | J21: =I21/B25 -> 0.23809524 | K21: =B24 -> 9 | L21: =K21/B25 -> 0.10714286
A22: Alto | B22: =COUNTIF('Bugs I'!C2:C85,'Indicadores I'!A22) -> 51
A23: Médio | B23: =COUNTIF('Bugs I'!C2:C85,'Indicadores I'!A23) -> 20
A24: Baixo | B24: =COUNTIF('Bugs I'!C5:C85,'Indicadores I'!A24) -> 9
A25: Total | B25: =SUM(B21:B24) -> 84
A28: OK | B28: =COUNTIF('Bugs I'!E2:E54,'Indicadores I'!A28) -> 0
A31: Bugs não resolvidos | B31: =B25-B28 -> 84
A36: FP | B36: =COUNTIF(Checklist!G$7:G$570,'Indicadores I'!A36) -> 109
A37: FA | B37: =COUNTIF(Checklist!G$7:G$570,'Indicadores I'!A37) -> 251
A38: FE | B38: =COUNTIF(Checklist!G$7:G$570,'Indicadores I'!A38) -> 108

Sheet Bugs II
A1: ID | B1: Título | C1: Criticidade | D1: Status Dev | E1: Status QA | F1: ESTÁ NO JIRA
A2: 145 | B2: Novo dashboard em branco não esta sendo criado | C2: Alto
A3: 555 - 556 | B3: Sistema não ajusta cores e bordas do item Linha em Formas | C3: Médio
A4: 366 | B4: Galeria de Gráficos demora mais de 1 minuto para carregar os gráficos da página | C4: Crítico
A5: 376 | B5: Botão "Recarregar Dados" da Galeria de Gráficos demora mais de 1 minuto para recarregar os gráficos | C5: Crítico
A6: 384 - 391 | B6: Card do gráfico exibe total de registros acima de 100 fora do padrão e alguns cards com menos de 100 registros não renderizam o gráfico | C6: Alto
A7: 398 | B7: Sistema esta mostrando numero maior que 100 diferente da regra estipulada | C7: Alto
A8: 580 | B8: Editor SQL — Mensagem de erro não tratada ao executar Preview com SQL inválido | C8: Baixo | F8: SIM
A9: 417 | B9: O Layout não se adapta; cards empilham; filtros acessíveis; gráficos redimensionam | C9: Médio
A10: 419 | B10: O Gráfico e painel lateral não se reorganizam; tabela com scroll; abas acessíveis | C10: Médio
A11: 583 | B11: Editor Python — Ausência de código de exemplo ao alternar para a aba Python | C11: Médio | F11: SIM
A12: 587 | B12: Editor Python — Mensagem de erro não tratada ao executar código com erro de runtime | C12: Baixo | F12: SIM
A13: 594 | B13: Assistente IA — Botões rápidos enviam prompts automáticos em inglês | C13: Baixo | F13: SIM
A14: 600 | B14: Assistente IA — Ausência de feedback contextual ao usar botão rápido com editor SQL vazio | C14: Alto | F14: SIM
A15: 606 | B15: Assistente IA — Status "Aplicado" exibido incorretamente em respostas negativas sem alteração de código | C15: Médio | F15: SIM
A16: 643 | B16: Assistente IA — Falha ao desfazer alterações via comando no chat gerando falso positivo | C16: Alto | F16: SIM
A17: 636 | B17: Mensagens de erro do Assistente IA exibidas em inglês | C17: Baixo | F17: SIM
A18: 636 | B18: Assistente IA interpreta clique na mensagem de erro como uma nova query SQL | C18: Alto | F18: SIM
A19: 570 | B19: Sistema Permite Salvar Gráfico com Nome Vazio | C19: Baixo | F19: SIM
A20: 585 | B20: IA Gera Código Python com Import de Biblioteca Proibida | C20: Alto | F20: SIM
A21: 631 | B21: Rodapé Ausente na Página do Editor de Gráficos | C21: Baixo | F21: SIM
A22: 633 | B22: Layout do Editor Quebra em Resolução Menor | C22: Baixo | F22: SIM
... A24: 647 | B24: Nenhuma Mensagem de Aviso ao Navegar com Alterações Não Salvas | C24: Alto | F24: SIM
B25: Gráfico Exibe Valores Negativos Após Sugestão da IA | C25: Alto | F25: SIM
B26: Aba "Dados" do Preview com Rolagem Infinita sem Paginação | C26: Baixo | F26: SIM

Sheet Planilha2
A3: Passed
A4: NA
A5: NT
A6: Failed

Sheet Indicadores II
A1: Executado | B1: =B2+B3 -> 195
A2: Passed | B2: =COUNTIF(Checklist!J7:J663,'Indicadores II'!A2) -> 170
A3: Failed | B3: =COUNTIF(Checklist!J8:J664,'Indicadores II'!A3) -> 25 | D3: Sprint | E3: Casos de testes | F3: Executados | G3: Indice de execução | H3: Passed | I3: Passed | J3: Failed | K3: Failed | L3: Não executado | M3: Indice de Incerteza
A4: NT | B4: =COUNTIF(Checklist!J9:J665,'Indicadores II'!A4) -> 0 | D4: BI com IA | E4: =B5 -> 195 | F4: =B1 -> 195 | G4: =F4/E4 -> 1 | H4: =B2 -> 170 | I4: =H4/F4 -> 0.87179487 | J4: =B3 -> 25 | K4: =J4/F4 -> 0.12820513 | L4: =B4 -> 0 | M4: =L4/E4 -> 0
A5: Total | B5: =SUM(B2:B4) -> 195
D19: Severidade
D20: Projeto | E20: Critico | F20: Critico | G20: Alto | H20: Alto | I20: Médio | J20: Médio | K20: Baixo | L20: Baixo
A21: Crítico | B21: =COUNTIF('Bugs II'!C$2:C26,'Indicadores II'!A21) -> 2 | D21: BI com IA | E21: =B21 -> 2 | F21: =E21/B25 -> 0.08 | G21: =B22 -> 10 | H21: =G21/B25 -> 0.4 | I21: =B23 -> 5 | J21: =I21/B25 -> 0.2 | K21: =B24 -> 8 | L21: =K21/B25 -> 0.32
A22: Alto | B22: =COUNTIF('Bugs II'!C$2:C27,'Indicadores II'!A22) -> 10
A23: Médio | B23: =COUNTIF('Bugs II'!C$2:C28,'Indicadores II'!A23) -> 5
A24: Baixo | B24: =COUNTIF('Bugs II'!C$2:C29,'Indicadores II'!A24) -> 8
A25: Total | B25: =SUM(B21:B24) -> 25
A28: OK | B28: =COUNTIF('Bugs I'!E2:E54,'Indicadores II'!A28) -> 0
A31: Bugs não resolvidos | B31: =B25-B28 -> 25
A35: Tela - Dashboard
A36: FP | B36: =SUM(COUNTIFS(Checklist!B:B,"=IA - Gráfico",Checklist!G:G,'Indicadores II'!A36),COUNTIFS(Checklist!B:B,"=Tela - Galeria de Graficos",Checklist!G:G,'Indicadores II'!A36),COUNTIFS(Checklist!B:B,"=Galeria de Gráficos",Checklist!G:G,'Indicadores II'!A36),COUNTIFS(Checklist!B:B,"=Tela Dashboards",Checklist!G:G,'Indicadores II'!A36)) -> 40
A37: FA | B37: =SUM(COUNTIFS(Checklist!B:B,"=IA - Gráfico",Checklist!G:G,'Indicadores II'!A37),COUNTIFS(Checklist!B:B,"=Tela - Galeria de Graficos",Checklist!G:G,'Indicadores II'!A37),COUNTIFS(Checklist!B:B,"=Galeria de Gráficos",Checklist!G:G,'Indicadores II'!A37),COUNTIFS(Checklist!B:B,"=Tela Dashboards",Checklist!G:G,'Indicadores II'!A37)) -> 79
A38: FE | B38: =SUM(COUNTIFS(Checklist!B:B,"=IA - Gráfico",Checklist!G:G,'Indicadores II'!A38),COUNTIFS(Checklist!B:B,"=Tela - Galeria de Graficos",Checklist!G:G,'Indicadores II'!A38),COUNTIFS(Checklist!B:B,"=Galeria de Gráficos",Checklist!G:G,'Indicadores II'!A38),COUNTIFS(Checklist!B:B,"=Tela Dashboards",Checklist!G:G,'Indicadores II'!A38)) -> 10

Sheet Dashboard Dados Gerais
B3: Visão Gerencial da qualidade de software ciclo I | AN3: Custo por Criticidade
AH4: ROI | AN4: Criticidade | AO4: Qtd | AP4: Custo unit. em QA | AQ4: Total em QA | AR4: Custo unit. em Produção (5x) | AS4: Total em Produção | AT4: Economia Gerada
AH5: Criticidade | AI5: Custo em QA | AJ5: Custo em Produção (5x) | AN5: 🔴 Crítico | AO5: 6 | AP5: 180.1 | AQ5: 1080.62 | AR5: 900.52 | AS5: 5403.11 | AT5: 4322.49
AH6: Crítico | AI6: 1080.62 | AJ6: 5403.11 | AN6: 🟠 Alto | AO6: 61 | AP6: 120.07 | AQ6: 7324.22 | AR6: 600.35 | AS6: 36621.1 | AT6: 29296.88
AH7: Alto | AI7: 7324.22 | AJ7: 36621.1 | AN7: 🟡 Médio | AO7: 25 | AP7: 60.03 | AQ7: 1500.86 | AR7: 300.17 | AS7: 7504.32 | AT7: 6003.46
B8: Total Cobertura CT´s | AH8: Médio | AI8: 1500.86 | AJ8: 7504.32 | AN8: 🟢 Baixo | AO8: 17 | AP8: 30.02 | AQ8: 510.29 | AR8: 150.09 | AS8: 2551.47 | AT8: 2041.18
Z9: Total Cobertura | AD9: % Não Testado | AH9: Baixo | AI9: 510.29 | AJ9: 2551.47 | AN9: TOTAL | AO9: 109 | AQ9: 10416 | AS9: 52079.99 | AT9: 41663.99
B10: ='Indicadores I'!$E$4 -> 502 | Z10: =B10+B51 -> 697 | AD10: =B27+B68 -> 0 | AH10: Total | AI10: 10416 | AJ10: 52079.99
Z11: FP | AA11: FA | AB11: FE
Z12: =B14+B55 -> 149 | AA12: =C14+C55 -> 330 | AB12: =D14+D55 -> 118
B13: FP | C13: FA | D13: FE
B14: ='Indicadores I'!B36 -> 109 | C14: ='Indicadores I'!B37 -> 251 | D14: ='Indicadores I'!B38 -> 108
AD15: Abertos | AH15: Categoria | AI15: Total | AJ15: Failed | AK15: Failed | AL15: Total
AC16: Crítico | AD16: ='Indicadores I'!B21+'Indicadores II'!B21 -> 6 | AH16: Funcionalidade | AI16: =COUNTIF(Checklist!H$7:H$663,'Dashboard Dados Gerais'!AH16) -> 227 | AJ16: =COUNTIFS(Checklist!H7:H663,'Dashboard Dados Gerais'!$AH16,Checklist!I7:I663,'Dashboard Dados Gerais'!$AJ$15) -> 18 | AK16: =COUNTIFS(Checklist!H7:H663,'Dashboard Dados Gerais'!$AH16,Checklist!J7:J663,'Dashboard Dados Gerais'!$AJ$15) -> 4 | AL16: =AK16+AJ16 -> 22
B17: Total Bug´s | Z17: Passed | AA17: ='Indicadores I'!B2+'Indicadores II'!B2 -> 591 | AC17: Alto | AD17: ='Indicadores I'!B22+'Indicadores II'!B22 -> 61 | AH17: Segurança | AI17: =COUNTIF(Checklist!H$7:H$663,'Dashboard Dados Gerais'!AH17) -> 62 | AJ17: =COUNTIFS(Checklist!H8:H664,'Dashboard Dados Gerais'!$AH17,Checklist!I8:I664,'Dashboard Dados Gerais'!$AJ$15) -> 8 | AK17: =COUNTIFS(Checklist!H8:H664,'Dashboard Dados Gerais'!$AH17,Checklist!J8:J664,'Dashboard Dados Gerais'!$AJ$15) -> 0 | AL17: =AK17+AJ17 -> 8
Z18: Failed | AA18: ='Indicadores I'!B3+'Indicadores II'!B3 -> 106 | AC18: Médio | AD18: ='Indicadores I'!B23+'Indicadores II'!B23 -> 25 | AH18: Sessão/Auth | AI18: =COUNTIF(Checklist!H$7:H$663,'Dashboard Dados Gerais'!AH18) -> 22 | AJ18: =COUNTIFS(Checklist!H9:H665,'Dashboard Dados Gerais'!$AH18,Checklist!I9:I665,'Dashboard Dados Gerais'!$AJ$15) -> 8 | AK18: =COUNTIFS(Checklist!H9:H665,'Dashboard Dados Gerais'!$AH18,Checklist!J9:J665,'Dashboard Dados Gerais'!$AJ$15) -> 0 | AL18: =AK18+AJ18 -> 8
B19: ='Indicadores I'!$B$25 -> 84 | Z19: NT | AA19: ='Indicadores I'!B4+'Indicadores II'!B4 -> 0 | AC19: Baixo | AD19: ='Indicadores I'!B24+'Indicadores II'!B24 -> 17 | AH19: Compatibilidade | AI19: =COUNTIF(Checklist!H$7:H$663,'Dashboard Dados Gerais'!AH19) -> 12 | AJ19: =COUNTIFS(Checklist!H10:H666,'Dashboard Dados Gerais'!$AH19,Checklist!I10:I666,'Dashboard Dados Gerais'!$AJ$15) -> 6 | AK19: =COUNTIFS(Checklist!H10:H666,'Dashboard Dados Gerais'!$AH19,Checklist!J10:J666,'Dashboard Dados Gerais'!$AJ$15) -> 2 | AL19: =AK19+AJ19 -> 8
Z20: Total | AA20: =SUM(AA17:AA19) -> 697 | AC20: Total | AD20: ='Indicadores I'!B25+'Indicadores II'!B25 -> 109 | AH20: Performance | AI20: =COUNTIF(Checklist!H$7:H$663,'Dashboard Dados Gerais'!AH20) -> 8 | AJ20: =COUNTIFS(Checklist!H11:H667,'Dashboard Dados Gerais'!$AH20,Checklist!I11:I667,'Dashboard Dados Gerais'!$AJ$15) -> 0 | AK20: =COUNTIFS(Checklist!H11:H667,'Dashboard Dados Gerais'!$AH20,Checklist!J11:J667,'Dashboard Dados Gerais'!$AJ$15) -> 1 | AL20: =AK20+AJ20 -> 1
AH21: Acessibilidade | AI21: =COUNTIF(Checklist!H$7:H$663,'Dashboard Dados Gerais'!AH21) -> 7 | AJ21: =COUNTIFS(Checklist!H12:H669,'Dashboard Dados Gerais'!$AH21,Checklist!I12:I669,'Dashboard Dados Gerais'!$AJ$15) -> 1 | AK21: =COUNTIFS(Checklist!H12:H669,'Dashboard Dados Gerais'!$AH21,Checklist!J12:J669,'Dashboard Dados Gerais'!$AJ$15) -> 0 | AL21: =AK21+AJ21 -> 1
AH22: Usabilidade | AI22: =COUNTIF(Checklist!H$7:H$663,'Dashboard Dados Gerais'!AH22) -> 52 | AJ22: =COUNTIFS(Checklist!H13:H670,'Dashboard Dados Gerais'!$AH22,Checklist!I13:I670,'Dashboard Dados Gerais'!$AJ$15) -> 3 | AK22: =COUNTIFS(Checklist!H13:H670,'Dashboard Dados Gerais'!$AH22,Checklist!J13:J670,'Dashboard Dados Gerais'!$AJ$15) -> 2 | AL22: =AK22+AJ22 -> 5
AH23: Conteúdo/UI | AI23: =COUNTIF(Checklist!H$7:H$663,'Dashboard Dados Gerais'!AH23) -> 66 | AJ23: =COUNTIFS(Checklist!H14:H671,'Dashboard Dados Gerais'!$AH23,Checklist!I14:I671,'Dashboard Dados Gerais'!$AJ$15) -> 1 | AK23: =COUNTIFS(Checklist!H14:H671,'Dashboard Dados Gerais'!$AH23,Checklist!J14:J671,'Dashboard Dados Gerais'!$AJ$15) -> 3 | AL23: =AK23+AJ23 -> 4
AH24: Integração | AI24: =COUNTIF(Checklist!H$7:H$663,'Dashboard Dados Gerais'!AH24) -> 14 | AJ24: =COUNTIFS(Checklist!H15:H672,'Dashboard Dados Gerais'!$AH24,Checklist!I15:I672,'Dashboard Dados Gerais'!$AJ$15) -> 5 | AK24: =COUNTIFS(Checklist!H15:H672,'Dashboard Dados Gerais'!$AH24,Checklist!J15:J672,'Dashboard Dados Gerais'!$AJ$15) -> 0 | AL24: =AK24+AJ24 -> 5
B25: % Não Testado | AH25: Notificação | AI25: =COUNTIF(Checklist!H$7:H$663,'Dashboard Dados Gerais'!AH25) -> 16 | AJ25: =COUNTIFS(Checklist!H16:H673,'Dashboard Dados Gerais'!$AH25,Checklist!I16:I673,'Dashboard Dados Gerais'!$AJ$15) -> 1 | AK25: =COUNTIFS(Checklist!H16:H673,'Dashboard Dados Gerais'!$AH25,Checklist!J16:J673,'Dashboard Dados Gerais'!$AJ$15) -> 0 | AL25: =AK25+AJ25 -> 1
AH26: Internacionalização | AI26: =COUNTIF(Checklist!H$7:H$663,'Dashboard Dados Gerais'!AH26) -> 4 | AJ26: =COUNTIFS(Checklist!H17:H674,'Dashboard Dados Gerais'!$AH26,Checklist!I17:I674,'Dashboard Dados Gerais'!$AJ$15) -> 1 | AK26: =COUNTIFS(Checklist!H17:H674,'Dashboard Dados Gerais'!$AH26,Checklist!J17:J674,'Dashboard Dados Gerais'!$AJ$15) -> 0 | AL26: =AK26+AJ26 -> 1
B27: ='Indicadores I'!$B$4 -> 0
Z29: Tela | AA29: Qtd Failed
Z30: IA - Chat | AA30: 29
B31: Bug´s Não Resolvidos | Z31: Tela - Nova Licença | AA31: 12 | AD31: Categoria | AE31: Ciclo I | AF31: Ciclo II | AG31: Total
Z32: IA - Gráfico | AA32: 13 | AD32: IA - Chat (Sem Categoria) | AE32: 29 | AF32: 0 | AG32: 29
B33: ='Indicadores I'!B31 -> 84 | Z33: Tela 01 - Login | AA33: 11 | AD33: Funcionalidade | AE33: 18 | AF33: 4 | AG33: 22
Z34: Tela - Galeria de Gráficos | AA34: 10 | AD34: IA - Gráfico (Sem Categoria) | AE34: 0 | AF34: 13 | AG34: 13
Z35: Controle de acesso | AA35: 5 | AD35: Segurança | AE35: 8 | AF35: 0 | AG35: 8
Z36: Tela de Chat | AA36: 5 | AD36: Compatibilidade | AE36: 6 | AF36: 2 | AG36: 8
Z37: Perfil: Distribuidor de licenças | AA37: 4 | AD37: Sessão/Auth | AE37: 8 | AF37: 0 | AG37: 8
Z38: Tela Dashboards | AA38: 4 | AD38: Integração | AE38: 5 | AF38: 0 | AG38: 5
Z39: Tela de Configurações | AA39: 3 | AD39: Usabilidade | AE39: 3 | AF39: 2 | AG39: 5
Z40: Perfil: Admin de Licença | AA40: 2 | AD40: Conteúdo/UI | AE40: 1 | AF40: 2 | AG40: 3
Z41: Galeria de Gráficos (Ciclo II) | AA41: 1 | AD41: Acessibilidade | AE41: 1 | AF41: 0 | AG41: 1
Z42: Tela - Criação de usuário | AA42: 1 | AD42: Internacionalização | AE42: 1 | AF42: 0 | AG42: 1
Z43: Telas Onboarding | AA43: 1 | AD43: Notificação | AE43: 1 | AF43: 0 | AG43: 1
...

Sheet Consolidado Bug´s
A1: Tipo de item | B1: Chave | C1: Resumo | D1: Responsável | E1: Relator | F1: Prioridade | G1: Status | H1: Resolução | I1: Criado | J1: Atualizado(a) | K1: Data limite
A2: Solicitação | B2: JBUG-116 | C2: Idéia - Inativar o botão quando não tem alterações nas configurações. | E2: Rodrigo Ferreira Mol | F2: Medium | G2: Bug`s / Pendências | I2: 46121.613 | J2: 46121.618 | Q2: Bug`s / Pendências | R2: Em Análise | S2: A fazer | T2: Corrigindo | U2: Concluido | V2: CANCELADO ❌
A3: Bug | B3: JBUG-115 | C3: CT 683 - Card de Notificação Agendada Não Exibe Badge "Inativa" Quando o Status é Inativo | D3: Michel Nunes Araujo | E3: Michel Nunes Araujo | F3: High | G3: Concluido | H3: Itens concluídos | I3: 46114.679 | J3: 46121.645 | N3: Bug | P3: Highest | Q3: =COUNTIFS($F:$F,$P3,$G:$G,Q$2) -> 0 | R3: =COUNTIFS($F:$F,$P3,$G:$G,R$2) -> 3 | S3: =COUNTIFS($F:$F,$P3,$G:$G,S$2) -> 0 | T3: =COUNTIFS($F:$F,$P3,$G:$G,T$2) -> 0 | U3: =COUNTIFS($F:$F,$P3,$G:$G,U$2) -> 2 | V3: =COUNTIFS($F:$F,$P3,$G:$G,V$2) -> 0
A4: Bug | B4: JBUG-111 | C4: CT 684 - Opção de Remoção de Notificação Agendada Não é Exibida na Aba Notificações | D4: Michel Nunes Araujo | E4: Michel Nunes Araujo | F4: High | G4: Concluido | H4: Itens concluídos | I4: 46114.637 | J4: 46120.616 | N4: =COUNTIF(A:A,N3) -> 112 | P4: High | Q4: =COUNTIFS($F:$F,$P4,$G:$G,Q$2) -> 7 | R4: =COUNTIFS($F:$F,$P4,$G:$G,R$2) -> 2 | S4: =COUNTIFS($F:$F,$P4,$G:$G,S$2) -> 0 | T4: =COUNTIFS($F:$F,$P4,$G:$G,T$2) -> 0 | U4: =COUNTIFS($F:$F,$P4,$G:$G,U$2) -> 42 | V4: =COUNTIFS($F:$F,$P4,$G:$G,V$2) -> 10
A5: Bug | B5: JBUG-110 | C5: CT 682 - Aba de Notificações nas Configurações Não Apresenta Responsividade Adequada em Resolução Desktop | D5: Michel Nunes Araujo | E5: Michel Nunes Araujo | F5: Medium | G5: Concluido | H5: Itens concluídos | I5: 46114.634 | J5: 46119.653 | P5: Medium | Q5: =COUNTIFS($F:$F,$P5,$G:$G,Q$2) -> 10 | R5: =COUNTIFS($F:$F,$P5,$G:$G,R$2) -> 2 | S5: =COUNTIFS($F:$F,$P5,$G:$G,S$2) -> 0 | T5: =COUNTIFS($F:$F,$P5,$G:$G,T$2) -> 0 | U5: =COUNTIFS($F:$F,$P5,$G:$G,U$2) -> 21 | V5: =COUNTIFS($F:$F,$P5,$G:$G,V$2) -> 3
A6: Bug | B6: JBUG-109 | C6: CT 674 - Lista de Notificações Agendadas Não Permite Scroll com Múltiplos Registros | D6: Michel Nunes Araujo | E6: Michel Nunes Araujo | F6: Medium | G6: Concluido | H6: Itens concluídos | I6: 46114.628 | J6: 46119.649 | P6: Low | Q6: =COUNTIFS($F:$F,$P6,$G:$G,Q$2) -> 5 | R6: =COUNTIFS($F:$F,$P6,$G:$G,R$2) -> 0 | S6: =COUNTIFS($F:$F,$P6,$G:$G,S$2) -> 0 | T6: =COUNTIFS($F:$F,$P6,$G:$G,T$2) -> 0 | U6: =COUNTIFS($F:$F,$P6,$G:$G,U$2) -> 6 | V6: =COUNTIFS($F:$F,$P6,$G:$G,V$2) -> 0
A7: Bug | B7: JBUG-108 | C7: CT280 – Sugestões de Perguntas do Chat Não Refletem Alterações de Permissão do Grupo de Acesso no Mesmo Dia | E7: Michel Nunes Araujo | F7: Medium | G7: Bug`s / Pendências | I7: 46113.64 | J7: 46113.641 | P7: Total | Q7: =SUM(Q3:Q6) -> 22 | R7: =SUM(R3:R6) -> 7 | S7: =SUM(S3:S6) -> 0 | T7: =SUM(T3:T6) -> 0 | U7: =SUM(U3:U6) -> 71 | V7: =SUM(V3:V6) -> 13
A8: Bug | B8: JBUG-107 | C8: Rótulos de dados sobrepostos no gráfico | E8: Rodrigo Ferreira Mol | F8: Medium | G8: Bug`s / Pendências | I8: 46113.358 | J8: 46113.36
A9: Bug | B9: JBUG-106 | C9: Aba "Dados" do Preview com Rolagem Infinita sem Paginação | E9: Jorge Alves | F9: Low | G9: Concluido | H9: Itens concluídos | I9: 46101.373 | J9: 46107.684
A10: Bug | B10: JBUG-105 | C10: Gráfico Exibe Valores Negativos Após Sugestão da IA | D10: Diego Preissler Arial | E10: Jorge Alves | F10: High | G10: Bug`s / Pendências | I10: 46101.372 | J10: 46107.435
A11: Bug | B11: JBUG-104 | C11: CT-647 Nenhuma Mensagem de Aviso ao Navegar com Alterações Não Salvas | E11: Jorge Alves | F11: High | G11: Bug`s / Pendências | I11: 46101.372 | J11: 46101.372
A12: Bug | B12: JBUG-103 | C12: CT-639 IA Sugere Query com View sem Permissão e Retorna Vazio Sem Aviso | D12: Diego Preissler Arial | E12: Jorge Alves | F12: High | G12: Bug`s / Pendências | I12: 46101.371 | J12: 46107.436
A13: Bug | B13: JBUG-102 | C13: CT-633 Layout do Editor Quebra em Resolução Menor | E13: Jorge Alves | F13: Low | G13: Bug`s / Pendências | I13: 46101.37 | J13: 46101.37
A14: Bug | B14: JBUG-101 | C14: CT-631 Rodapé Ausente na Página do Editor de Gráficos | D14: Jorge Alves | E14: Jorge Alves | F14: Low | G14: Concluido | H14: Itens concluídos | I14: 46101.369 | J14: 46121.526
A15: Bug | B15: JBUG-100 | C15: CT-585 IA Gera Código Python com Import de Biblioteca Proibida | D15: Diego Preissler Arial | E15: Jorge Alves | F15: High | G15: Bug`s / Pendências | I15: 46101.369 | J15: 46107.437
A16: Bug | B16: JBUG-99 | C16: CT-570 Sistema Permite Salvar Gráfico com Nome Vazio | D16: Jorge Alves | E16: Jorge Alves | F16: Low | G16: Concluido | H16: Itens concluídos | I16: 46101.368 | J16: 46120.622
A17: Bug | B17: JBUG-98 | C17: CT-636 Assistente IA interpreta clique na mensagem de erro como uma nova query SQL | D17: Diego Preissler Arial | E17: Jorge Alves | F17: High | G17: Bug`s / Pendências | I17: 46100.93 | J17: 46107.435
A18: Bug | B18: JBUG-97 | C18: CT-636 Mensagens de erro do Assistente IA exibidas em inglês | E18: Jorge Alves | F18: Low | G18: Bug`s / Pendências | I18: 46100.929 | J18: 46100.929
A19: Bug | B19: JBUG-96 | C19: CT-643 Assistente IA — Falha ao desfazer alterações via comando no chat gerando falso positivo | D19: Diego Preissler Arial | E19: Jorge Alves | F19: High | G19: Bug`s / Pendências | I19: 46099.91 | J19: 46107.435
A20: Bug | B20: JBUG-95 | C20: CT-606 Assistente IA — Status "Aplicado" exibido incorretamente em respostas negativas sem alteração de código | D20: Diego Preissler Arial | E20: Jorge Alves | F20: Medium | G20: Bug`s / Pendências | I20: 46099.906 | J20: 46107.435
A21: Bug | B21: JBUG-94 | C21: CT-600 Assistente IA — Ausência de feedback contextual ao usar botão rápido com editor SQL vazio | D21: Diego Preissler Arial | E21: Jorge Alves | F21: High | G21: Bug`s / Pendências | I21: 46099.903 | J21: 46107.435
A22: Bug | B22: JBUG-93 | C22: CT-594 Assistente IA — Botões rápidos enviam prompts automáticos em inglês | D22: Diego Preissler Arial | E22: Jorge Alves | F22: Low | G22: Bug`s / Pendências | I22: 46099.9 | J22: 46107.435
A23: Bug | B23: JBUG-92 | C23: CT-587 Editor Python — Mensagem de erro não tratada ao executar código com erro de runtime | E23: Jorge Alves | F23: Low | G23: Bug`s / Pendências | I23: 46099.898 | J23: 46107.438
A24: Bug | B24: JBUG-91 | C24: CT-583 Editor Python — Ausência de código de exemplo ao alternar para a aba Python | E24: Jorge Alves | F24: Medium | G24: Bug`s / Pendências | I24: 46099.894 | J24: 46099.894
A25: Bug | B25: JBUG-90 | C25: CT-580 Editor SQL — Mensagem de erro não tratada ao executar Preview com SQL inválido | E25: Jorge Alves | F25: Low | G25: Bug`s / Pendências | I25: 46099.877 | J25: 46099.877
A26: Bug | B26: JBUG-89 | C26: CT 398 – Na Aba gráfico o Card do gráfico exibe total de registros acima de 100 fora do padrão e alguns cards com menos de 100 registros não renderizam o gráfico | D26: Rodrigo Ferreira Mol | E26: Rodrigo Ferreira Mol | F26: High | G26: Concluido | H26: Itens concluídos | I26: 46098.707 | J26: 46112.897
A27: Bug | B27: JBUG-88 | C27: CT 384 – CT 391 –Na galeria o Card do gráfico exibe total de registros acima de 100 fora do padrão e alguns cards com menos de 100 registros não renderizam o gráfico | D27: Rodrigo Ferreira Mol | E27: Rodrigo Ferreira Mol | F27: High | G27: Concluido | H27: Itens concluídos | I27: 46098.706 | J27: 46112.902
A28: Bug | B28: JBUG-87 | C28: CT 376 - Botão "Recarregar Dados" da Galeria de Gráficos demora mais de 1 minuto para recarregar os gráficos | D28: Rodrigo Ferreira Mol | E28: Rodrigo Ferreira Mol | F28: Highest | G28: Em Análise | I28: 46098.704 | J28: 46107.624
A29: Bug | B29: JBUG-86 | C29: CT 366 - Galeria de Gráficos demora mais de 1 minuto para carregar os gráficos da página | D29: Rodrigo Ferreira Mol | E29: Rodrigo Ferreira Mol | F29: Highest | G29: Em Análise | I29: 46098.703 | J29: 46107.624
A30: Bug | B30: JBUG-85 | C30: CT 555 – CT 556 - Sistema não ajusta cores e bordas do item Linha em Formas | E30: Rodrigo Ferreira Mol | F30: Medium | G30: Bug`s / Pendências | I30: 46098.686 | J30: 46098.71
A31: Bug | B31: JBUG-84 | C31: CT 145 - Novo dashboard em branco não esta sendo criado | D31: Rodrigo Ferreira Mol | E31: Rodrigo Ferreira Mol | F31: High | G31: Concluido | H31: Itens concluídos | I31: 46094.476 | J31: 46107.637
A32: Bug | B32: JBUG-83 | C32: CT-233 - Sessão do Usuário Inativado Permanece Aberta com Erros de Conexão em Vez de Encerramento Adequado | D32: Jorge Alves | E32: Jorge Alves | F32: Medium | G32: Concluido | H32: Itens concluídos | I32: 46093.662 | J32: 46121.536
A33: Bug | B33: JBUG-82 | C33: CT81 Modal de Sugestões de Perguntas com Layout Quebrado em Telas ≤ 18 Polegadas (Zoom 100%) | E33: Jorge Alves | F33: Medium | G33: CANCELADO ❌ | I33: 46093.632 | J33: 46098.34
A34: Bug | B34: JBUG-81 | C34: CT 64 - Onboarding Reexibido em Todo Login do Usuário | D34: Jorge Alves | E34: Jorge Alves | F34: Medium | G34: Concluido | H34: Itens concluídos | I34: 46093.617 | J34: 46121.463
A35: Bug | B35: JBUG-80 | C35: Exibição de Licença de Distribuidor ao Realizar Login com Usuário ADM | E35: Jorge Alves | F35: High | G35: Concluido | H35: Itens concluídos | I35: 46093.606 | J35: 46107.347
A36: Bug | B36: JBUG-79 | C36: CT 516 - Chat Permite Envio de Mensagem Muito Longa Gerando Erro de Conexão | E36: Jorge Alves | F36: High | G36: Concluido | H36: Itens concluídos | I36: 46092.773 | J36: 46107.458
A37: Bug | B37: JBUG-78 | C37: CT 527 - IA Não Resolve Anáfora — Ignora Resposta Anterior na Mesma Sessão | E37: Jorge Alves | F37: High | G37: Concluido | H37: Itens concluídos | I37: 46092.772 | J37: 46107.503
A38: Bug | B38: JBUG-77 | C38: CT 524 - IA Afirma Ter Memória de Sessão Anterior em Nova Sessão | E38: Jorge Alves | F38: High | G38: Concluido | H38: Itens concluídos | I38: 46092.771 | J38: 46107.593
A39: Bug | B39: JBUG-76 | C39: CT 524 - IA Vaza Contexto de Sessão Anterior ao Ser Perguntada | E39: Jorge Alves | F39: High | G39: Concluido | H39: Itens concluídos | I39: 46092.771 | J39: 46107.591
A40: Bug | B40: JBUG-75 | C40: CT 513 - Tooltip Duplicado ao Hover no Ícone de Microfone | D40: Jorge Alves | E40: Jorge Alves | F40: High | G40: Concluido | H40: Itens concluídos | I40: 46092.769 | J40: 46113.716
...

Sheet Dashboard Consolidado
B2: Visão Gerencial da qualidade de software ciclo I e II
B7: Total Cobertura CT´s
B9: ='Dashboard Dados Gerais'!Z10 -> 697
B12: FP | C12: FA | D12: FE
B13: ='Dashboard Dados Gerais'!Z12 -> 149 | C13: ='Dashboard Dados Gerais'!AA12 -> 330 | D13: ='Dashboard Dados Gerais'!AB12 -> 118
B16: Total Bug´s
B18: ='Consolidado Bug´s'!N4 -> 112
B59: Bug`s / Pendências
B62: Crítico | G62: Alto | M62: Médio | R62: Baixo
B64: ='Consolidado Bug´s'!Q3 -> 0 | G64: ='Consolidado Bug´s'!Q4 -> 7 | M64: ='Consolidado Bug´s'!Q5 -> 10 | R64: ='Consolidado Bug´s'!Q6 -> 5
B67: Em Análise
B70: Crítico | G70: Alto | M70: Médio | R70: Baixo
B72: ='Consolidado Bug´s'!R3 -> 3 | G72: ='Consolidado Bug´s'!R4 -> 2 | M72: ='Consolidado Bug´s'!R5 -> 2 | R72: ='Consolidado Bug´s'!R6 -> 0
B75: A Fazer
B78: Crítico | G78: Alto | M78: Médio | R78: Baixo
B80: ='Consolidado Bug´s'!S3 -> 0 | G80: ='Consolidado Bug´s'!S4 -> 0 | M80: ='Consolidado Bug´s'!S5 -> 0 | R80: ='Consolidado Bug´s'!S6 -> 0
B83: Em Testes
B86: Crítico | G86: Alto | M86: Médio | R86: Baixo
B88: ='Consolidado Bug´s'!T3 -> 0 | G88: ='Consolidado Bug´s'!T4 -> 0 | M88: ='Consolidado Bug´s'!T5 -> 0 | R88: ='Consolidado Bug´s'!T6 -> 0
B91: Concuido
B94: Crítico | G94: Alto | M94: Médio | R94: Baixo
B96: ='Consolidado Bug´s'!U3 -> 2 | G96: ='Consolidado Bug´s'!U4 -> 42 | M96: ='Consolidado Bug´s'!U5 -> 21 | R96: ='Consolidado Bug´s'!U6 -> 6
B99: Cancelados
B102: Crítico | G102: Alto | M102: Médio | R102: Baixo
B104: ='Consolidado Bug´s'!V3 -> 0 | G104: ='Consolidado Bug´s'!V4 -> 10 | M104: ='Consolidado Bug´s'!V5 -> 3 | R104: ='Consolidado Bug´s'!V6 -> 0
